|#|Log Error Scanerio|Log Error Description|
|--|--|--|
|1.|Connectivity Issue |Connection error occured<br>Traceback (most recent call last):<br>File "C:\Users\hhoney\PycharmProjects\pythonProject1\venv\lib\site-packages\urllib3\connection.py", line 160, in _new_conn<br>(self._dns_host, self.port), self.timeout, **extra_kw<br>
  File "C:\Users\hhoney\PycharmProjects\pythonProject1\venv\lib\site-packages\urllib3\util\connection.py", line 61, in create_connection<br>for res in socket.getaddrinfo(host, port, family, socket.SOCK_STREAM<br>File "C:\Users\hhoney\AppData\Local\Programs\Python\Python37-32\lib\socket.py", line 748, in getaddrinfo<br>for res in _socket.getaddrinfo(host, port, family, type, proto, flags):<br>socket.gaierror: [Errno 11001] getaddrinfo failed|

